Workbook

Sheet Participants-Parties
A1: Opened - Day | B1: Opened - Time | C1: Party | D1: Job | E1: Status | F1: Priority | G1: Situation | H1: Type
A2: Satuday | B2: 0.54166667 | C2: Clairia | D2: Keeper | E2: Hopefully fixed | F2: Low | G2: Keeper tweaked an ankle while walking. Sounds minor, but should have a medical check-in at lunch. -Scaz Kristi - JulieL checked her out and she's fine. "It hurt for a sec; it's fine now." | H2: Medical
A3: Friday | B3: 0.78125 | C3: P'Loa | E3: Hopefully fixed | F3: High | G3: participant suddenly feeling light-headed, sweaty; Steve found Abigail. Julie Leviter checking in on him. Maisie's husband is being sent to hospiatal. Ab called 911 Maise (compantion) may be going with him. Jodi 6:50 Maise is going with her husband ... Tennile is talkin to Joyce about being doloron companion for evening jodi 7:15 | H3: Medical
A4: Friday | B4: 0.77083333 | C4: Uri-Kesh | D4: Traveler | E4: Hopefully fixed | F4: Low | G4: Linda walked a participant from urikesh through the basement staff area with eyes closed. Linda said she had been feeling overwhelmed. Talked to Bill later and participant had gone stragiht into combat workshops. He didn't know how that went. - jodi fri 6:50 Chris - checked in with Bill; he is "not concerned at the moment". They're getting ready to leave the tavern now 8:30pm Kristi - Raja (the traveler) approached Linda (as Valentina) and says she's doing fine now. Let's check in with Bill in the morning but if she's still good, we can call this hopefully fixed. I downgraded this to Low. (10:30pm) Kristi - Bill is not worried. Closing this (8:45am)
A5: Friday | B5: 0.8125 | C5: Doloron | D5: Other | E5: Hopefully fixed | F5: Low | G5: joyce will be companion for doloron friday night. She is delivering her contact info to her party and then will meet up with doloron. She is willing to keep going as companion past today if needed and says her schedule is pretty clear. (trial coordinator for claria sunday) jodi 7:40 joyce says that since son does not have a guardian ... worth it to get a medical power attorney
A6: Friday | B6: 0.91666667 | C6: P'Loa | D6: Keeper | E6: Hopefully fixed | F6: Low | G6: Kristi - Maisie mentioned that Orlando (real name) was nervous about attending but was feeling comfortable because he's with Matt. Matt isn't coming back so we're just making sure Orlando is having fun and not getting too anxious. (10pm) Kristi - JenP had an early encounter with Orlando and he was given coffee and is in good spirits (7:30am)
A7: Satuday | B7: 0.3125 | C7: Sythwan | D7: Seeker | E7: Hopefully fixed | F7: Low | G7: Kristi - We have a participant in Clairia (Kai) who's flying out of Logan at 8pm on Sunday. Would Caro (Seeker) be willing to drive her on Sunday? If not, we have other options but Caro is the best. Give answer to MattM after we know. (7:30am) Kristi - Lori is going to ask Caro. I told her a No now is better than a Yes that changes later. (9:15am) Kristi - DaveN says Lori says Caro says Yes. Yay! Telling MattM (9:18am)
A8: Friday | B8: 0.95833333 | C8: Noctara | D8: Other | E8: Hopefully fixed | F8: Low | G8: Melissa (recorded by Reichert)Provided party with 5 towels from the comfort comittee
A9: Satuday | B9: 0.33333333 | C9: Doloron | D9: Other | E9: Hopefully fixed | F9: High | G9: Chris -- Need to ask Joyce for her input on handing out party path items today. War Band is ready to take over for her, want to confirm that she is OK with this
A10: Satuday | B10: 0.375 | C10: Keer | D10: Seeker | E10: Hopefully fixed | F10: Low | G10: Ari a bit tired, might need a nap later, we'll see (CR)
A11: Satuday | B11: 0.375 | C11: Waylon | D11: Maker | E11: Hopefully fixed | F11: Low | G11: CR: Companion syas Tarik (Maker ) and SLedge (Keeper) would be good to pair with magic items, will help them engage a bite more | H11: Opportunity!
A12: Satuday | B12: 0.375 | C12: Clairia | D12: Maker | E12: Hopefully fixed | F12: Low | G12: Tasar? is tired this morning (blue hair) (group in general has a bit of morning grumbling). There is a 3:3 split between moving slow and getting going.(CR)
A13: Satuday | B13: 0.375 | C13: Elsewhich | D13: Other | E13: Hopefully fixed | F13: Low | G13: Would be good to pair magic items across internal lines (per companion brief) (CR) | H13: Opportunity!
A14: Satuday | B14: 0.52083333 | C14: Uri-Kesh | D14: Seeker | E14: Hopefully fixed | F14: High | G14: Seeker from Uri-Kesh is asking to go home. Spoke with CR on the tavern porch. He's clear on his reasons and we think getting him away from the rest of the party ASAP is the right move. He came alone and has his own car. Sending him out as of lunch. -BS 12:30 CR: Gray is gone
A15: Satuday | B15: 0.66666667 | C15: Sythwan | D15: Other | E15: Hopefully fixed | F15: High | G15: Kristi - Not a problem; just please give Lori the Sunday morning keeper vision! Thank you! :) | H15: Opportunity!
A16: Satuday | B16: 0.54166667 | C16: Uri-Kesh | D16: Traveler | E16: Hopefully fixed | F16: Low | G16: Needs a lunch time check in to verify that she is on track
A17: Satuday | B17: 0.35416667 | C17: Noctara | D17: Other | E17: Hopefully fixed | F17: Low | G17: CR: Via companion, they are really into Banshee lore, Pendant of Fortune d'Oro would be a big win for them RD: Told Margot before she went out. We'll try. j: they did get the pendant ..recognized immediately and were very excited. | H17: Opportunity!
A18: Satuday | B18: 0.375 | C18: Keer | D18: Ranger | E18: Hopefully fixed | F18: Low | G18: Kristi - BobM reports that Nietz (Martin) is holding himself apart. Not worried about it yet but worth keeping an eye on. (He was supposed to be here with his daughter but she had to cancel last minute. Also note that Martin lost a son to an overdose a couple years back so please just watch this as grief/Rites plot ramps up. - this is just Kristi talking, not BobM) (9am) CR-Companion reports that this is improving but should remain monitored)
A19: Satuday | B19: 0.375 | C19: Clairia | D19: Traveler | E19: Monitoring | F19: Low | G19: Obscura is terrified to be here, need to bring her into things with some attention, suggested hitting som eupbeat sites this AM, like peacocks (CR) Traveler requested first a cane (given by MMiles at 12:00) and then a knee brace and wrap (given by companion at 12:20). We should have one the medical staff check in at lunch with her. -BS, 12:20SAT 1:15 (CR) Julie L checked in with Natalie, she is coping but may need accomodation at 8[pm meeting. Kristi - JulieL talked to her again. She doesn't want to let her group down. She doesn't know the others in the group (besides her boyfriend and friend) and is feeling worried about letting them down. The pain is her baseline; she's dealing with it. Julie is reinforcing that it's okay to take naps or breaks or to speak up. Julie was also telling her that the story is going to get scarier; that's not her, it's just how the story is. (1:45pm) Scaz: Julie checked on her again at 4pm. Thinks she's doing ok. Jodi: gave her and other clarian resting in front of the tavern charge information. They were looking to get back with with group, had been planning on investigating the morg for danny charge (but it was a ghost theater). A bit timid but engaged. | H19: Medical
A20: Satuday | B20: 0.54166667 | C20: Glendeep | D20: Other | E20: Monitoring | F20: Low | G20: CR: Opportunity for magic: They've been giving out SHell bracelets, would be cool to work this in or ackbnowledge | H20: Opportunity!
A21: Satuday | B21: 0.54166667 | C21: Glendeep | D21: Traveler | E21: Hopefully fixed | F21: Low | G21: CR: Has a past ankle injury, fine for now but Brian is keeping a compression bandage on him in case he needs it later JL is talking to this participant Fine as of dinner SAT - scaz
A22: Satuday | B22: 0.58333333 | C22: Doloron | D22: Caster | E22: Hopefully fixed | F22: Low | G22: Caster is a little fixated on rules and doing it "right". Is putting a lot of pressure on himself that he only gets to do this once and doesn't want to screw it up. I encouraged him to take breaks, focus on being in a story, to understand that sometimes the dice go cold and sometimes dice are cocked and you need to just decide what makes a good story and go with it. He understood this intellectually but let's see if he can embody it. Companion says things are resolved - Scaz, dinner Sat
A23: Satuday | B23: 0.625 | C23: Clairia | D23: Other | E23: Hopefully fixed | F23: Low | G23: Clairia is splitting up. Some are napping. One is going to rest their knee at the tavern. Rest are going. Someone needs to do the 4pm "Sky turns black" at the tavern. Rob (4pm) - Julie talked to the people and they said their health is fine. I think they are a little checked out but they may just be quiet. I told them the sky turned black.
A24: Satuday | B24: 0.70833333 | C24: Uri-Kesh | D24: Other | E24: Fixing | F24: Low | G24: Party disregarded Poppy's admonishment to stay out of the Court of Mirrors. She repeatedly told them not to enter, increasing severity. They ultimately entered and shut the door behind them without really acknowledging her. Should Poppy address them directly at dinner that this was disrespectful/otherwise?- laura's thought is that they are disregarding 'side characters as people'... not personally as an staff person but in the adventure. Abigail & Jodi Companion thinks that they were trying to disregard the gold-faced characters because of all the changes. Haven't seen this problem anywhere else. Suggests that we send Poppy to them at dinner to add on some guilt. -scaz
A25: Satuday | B25: 0.77083333 | C25: Sythwan | D25: Other | E25: Hopefully fixed | F25: Low | G25: Sythwan would like an early soulspeaking if possible | H25: Opportunity!
A26: Satuday | B26: 0.77083333 | C26: Clairia | D26: Other | E26: Hopefully fixed | F26: Low | G26: Might have dropped a book. Might have dropped a rope
A27: Satuday | B27: 0.77083333 | C27: Elsewhich | D27: Other | E27: Hopefully fixed | F27: Low | G27: Might have dropped a rope. Kristi - they don't need it again (Sun 7am)
A28: Satuday | B28: 0.85416667 | C28: Doloron | D28: Traveler | E28: Monitoring | F28: Low | G28: Kristi - is there really not an entry on the Doloron traveler yet? Weird. Anyway, he's noping out of the Saturday night activities, including being driven to the crypt. "I've pushed myself way too hard." Yeah, no shit, dude. But he's sitting in the tavern and seems okay with that. Keeping an eye on but hopefully okay. (8:40pm)
A29: Sunday | B29: 0.375 | C29: Glendeep | D29: Seeker | E29: Hopefully fixed | F29: Low | G29: CR: Note for future: Seeker was disappointed by the Wolven battle, felt like a meat shield and not a hero | H29: Opportunity!

Sheet StaffCamp
A1: Opened - Day | B1: Opened - Time | C1: Staff | D1: Status | E1: Priority | F1: Situation | G1: Type
A2: Satuday | B2: 0.66666667 | C2: Peggy O'Connell | D2: Hopefully fixed | E2: Low | F2: Peggy is at the Air-BNB icing her knee. Will be back for 8pm duty. -scaz | J2: Bill Sabram
A3: Satuday | B3: 0.35416667 | C3: Chris Reichert | D3: Hopefully fixed | E3: Low | F3: CR: Note to future, do wqe need to put towels on the participant packing list? | G3: Opportunity! | J3: Anna Kelly
A4: Satuday | B4: 0.33333333 | C4: Chris Reichert | D4: Hopefully fixed | E4: Low | F4: Chris: Obtain more toilet paper from camp, need to talk to Heather, texted her at 8:10am Says she will be here before lunch time CR: Toilet paper surplus place in the single use bathroom, more industrial paper towel rolls are in the downstairs supply closet | J4: Alison Morris
A5: Satuday | B5: 0.39583333 | C5: camp | D5: Hopefully fixed | E5: Low | F5: Kristi: Chelsea reports (via Rowan) that the Hillcrest bathroom has a leaky toilet (which we think is just how it is) and a jammed paper towel dispenser and is low on toilet paper. Sending GregRo up to hopefully address at least 2 of these (9:45am) CR: 11:07, Out of Order signs placed on the toilets, more TP is available in the EM bathroom | J5: Ariel Jaffee
A6: Set Up | B6: 0.54166667 | C6: Kelsey Schultz | D6: Monitoring | E6: Low | F6: Kelsey has had a lot going on this year and feels a bit fragile/unfocused. Might need extra attention and/or care. -RD | J6: Aaron Size
A7: Set Up | B7: 0.75 | C7: Diana Galanakis | D7: Monitoring | E7: Low | F7: Reminder that Diana is pregnant and this is not public knowledge but she might get tired, etc. etc.. - RD | J7: Abigail Vargus
A8: Set Up | B8: 0.375 | C8: Kayla Schlenz | D8: Monitoring | E8: Low | F8: Kayla hurt her knee this week so might have limited mobility - RD | J8: Alex Sheehan
A9: Satuday | B9: 0.35416667 | C9: Michelle Nathan | D9: Monitoring | E9: Low | F9: Michelle is physically and mentally at low ebb. She will eat breakfast downstairs, get a ride to the Valerius house, and would like someone else to take her madlibs ander duty so that she can be Iolanthe.-AMV Chris (9:27): Tenille is taking over the Madlib Ander | J9: Ana Quintana
A10: Satuday | B10: 0.5 | C10: Jim Vincent | D10: Fixing | E10: High | F10: CR: Jim injured his ankle on a porch trip. Gave ice pack and Tylenol, needs medical follow up. CR: Dana treated at 12:30pm, confirmed ice and elevation, needs follow up in a few hours CR (2:30): Flag for Julie L to examine | J10: Ben Warren
A11: Satuday | B11: 0.75 | C11: Katherine Greene | D11: Fixing | E11: High | F11: Katherine was approached by a staff in an ander mask to address her conversation about combat in last year's event. She is very upset. Scaz is talking to her.-AMV Much of this seems to revolve around conversation with Tricia. Katherine's still very upset, but is moving forward with her role for the alt timeline. We will likely need to have a sit-down with Katherine and Tricia later. -scaz J: Tricia saw Katherine and Scaz talking and has been eyeing the table after getting back from her monster shift, but not engaging with us. Scaz and Ab briefed Reichert and he is going to talk to Tricia to say that we are aware that something went on and we can talk through it later and hear her side (after tonights festivities). 7:40 | J11: Bob Coury
A12: Satuday | B12: 0.66666667 | C12: Peggy O'Connell | D12: Hopefully fixed | E12: Low | F12: peg went back to hotel to ice her knee. She will be back for evening activies J: she is back | J12: Blake Geno
A13: Satuday | B13: 0.79166667 | C13: Nils Klinkenberg | D13: Monitoring | E13: Low | F13: A cane broke in ghost theater. Is it also his? Check. - Rob Kristi - the broken cane that's on the EM desk is Edwin Davies' and Otherworld's. The sunday vision references the cane but I think we can fix it enough if Nils needs to clue hammer the party tomorrow (8:30) | J13: Bob Marriott
J14: Bri Taborn
J15: Brian Neff
J16: Brian Scassellati
J17: Britt Rothauser
J18: Cecilia Lindgren
J19: Charlotte Wilson
J20: Chelsea Hadlock
J21: Chris Reichert
J22: Christine Huebbe
J23: Christine Reeves
J24: Cliff Young
J25: Cris Shuldiner
... J114: Zak Terry
D129: Hopefully fixed | F129: asdfadsf
A134: Satuday | B134: 0.58333333 | C134: Jeff Yaus | D134: Hopefully fixed | E134: Low | F134: Jeff was serving lunch to Carmina/Michelle, who was in character in front of many participants. He responded to her imperious nature by whispering to her that she should "tone it down at lunch." Michelle (already struggling with being mean) found this hurtful although she said venting about it was enough. I find it boundary-crossing-AMV ... 4pm: talked to Jeff, he believed he was asking for space to serve participants, will clarify w Michelle, apologized and thanked me.-AMV | J134: Betsy Rosenblatt

Sheet Dashboard
B1: Saturday | F1: Sunday
B2: Breakfast | C2: Vision? | D2: Lunch | E2: Dinner | F2: Breakfast | G2: Vision? | H2: Party Path | I2: Cup of Insight? | J2: Got Riddle? | K2: Combats | L2: Open Issues | M2: Got Riddle Item?
A3: Arden | B3: TRUE | C3: TRUE | D3: TRUE | E3: TRUE | F3: TRUE | G3: TRUE | H3: ='All Party Summary'!B2 -> 8/8 | I3: ='All Party Summary'!C2 -> Yes! | J3: ='All Party Summary'!D2 -> Yes! | K3: ='All Party Summary'!F2 -> 9 | L3: =COUNTIFS('Participants-Parties'!$C:$C, A3,'Participants-Parties'!$E:$E, "<>Hopefully Fixed") -> 0 | M3: TRUE | P3: Saturday Breakfast Questions - Vibe check and vision confirmation
A4: Clairia | B4: TRUE | C4: TRUE | D4: TRUE | E4: TRUE | F4: TRUE | G4: TRUE | H4: ='All Party Summary'!B3 -> 8/8 | I4: ='All Party Summary'!C3 -> Yes! | J4: ='All Party Summary'!D3 -> Yes! | K4: ='All Party Summary'!F3 -> 5 | L4: =COUNTIFS('Participants-Parties'!$C:$C, A4,'Participants-Parties'!$E:$E, "<>Hopefully Fixed") -> 1 | M4: FALSE | O4: 1 | P4: How are you doing?
A5: Doloron | B5: TRUE | C5: TRUE | D5: TRUE | E5: TRUE | F5: TRUE | G5: TRUE | H5: ='All Party Summary'!B4 -> 7/8 | I5: ='All Party Summary'!C4 -> Yes! | J5: ='All Party Summary'!D4 -> Yes! | K5: ='All Party Summary'!F4 -> 7 | L5: =COUNTIFS('Participants-Parties'!$C:$C, A5,'Participants-Parties'!$E:$E, "<>Hopefully Fixed") -> 1 | M5: FALSE | O5: 2 | P5: How did everybody sleep?
A6: Elsewhich | B6: TRUE | C6: TRUE | D6: TRUE | E6: TRUE | F6: TRUE | G6: TRUE | H6: ='All Party Summary'!B5 -> 8/8 | I6: ='All Party Summary'!C5 -> Yes! | J6: ='All Party Summary'!D5 -> Yes! | K6: ='All Party Summary'!F5 -> 7 | L6: =COUNTIFS('Participants-Parties'!$C:$C, A6,'Participants-Parties'!$E:$E, "<>Hopefully Fixed") -> 0 | M6: TRUE | O6: 3 | P6: How’s everybody feeling this morning?
A7: Glendeep | B7: TRUE | C7: TRUE | D7: TRUE | E7: TRUE | F7: TRUE | G7: TRUE | H7: ='All Party Summary'!B6 -> 7/8 | I7: ='All Party Summary'!C6 -> Yes! | J7: ='All Party Summary'!D6 -> Yes! | K7: ='All Party Summary'!F6 -> 8 | L7: =COUNTIFS('Participants-Parties'!$C:$C, A7,'Participants-Parties'!$E:$E, "<>Hopefully Fixed") -> 1 | M7: TRUE | O7: 4 | P7: Was the Keeper given their vision? Did they share it? Did anyone have thoughts about it?
A8: Keer | B8: TRUE | C8: TRUE | D8: TRUE | E8: TRUE | F8: TRUE | G8: TRUE | H8: ='All Party Summary'!B7 -> 8/8 | I8: ='All Party Summary'!C7 -> Yes! | J8: ='All Party Summary'!D7 -> Yes! | K8: ='All Party Summary'!F7 -> 9 | L8: =COUNTIFS('Participants-Parties'!$C:$C, A8,'Participants-Parties'!$E:$E, "<>Hopefully Fixed") -> 0 | M8: TRUE | O8: 5 | P8: Do they remember they have the list of things to find today?
A9: Noctara | B9: TRUE | C9: TRUE | D9: TRUE | E9: TRUE | F9: TRUE | G9: TRUE | H9: ='All Party Summary'!B8 -> 8/8 | I9: ='All Party Summary'!C8 -> Yes! | J9: ='All Party Summary'!D8 -> Yes! | K9: ='All Party Summary'!F8 -> 8 | L9: =COUNTIFS('Participants-Parties'!$C:$C, A9,'Participants-Parties'!$E:$E, "<>Hopefully Fixed") -> 0 | M9: TRUE | O9: 6 | P9: Are there any challenges among people in the group?
A10: P'loa | B10: TRUE | C10: TRUE | D10: TRUE | E10: TRUE | F10: TRUE | G10: TRUE | H10: ='All Party Summary'!B9 -> 8/8 | I10: ='All Party Summary'!C9 -> Yes! | J10: ='All Party Summary'!D9 -> Yes! | K10: ='All Party Summary'!F9 -> 8 | L10: =COUNTIFS('Participants-Parties'!$C:$C, A10,'Participants-Parties'!$E:$E, "<>Hopefully Fixed") -> 0 | M10: TRUE | O10: 7 | P10: Anyone we should be keeping an eye on?
A11: Sythwan | B11: TRUE | C11: TRUE | D11: TRUE | E11: TRUE | F11: TRUE | G11: TRUE | H11: ='All Party Summary'!B10 -> 8/8 | I11: ='All Party Summary'!C10 -> Yes! | J11: ='All Party Summary'!D10 -> Yes! | K11: ='All Party Summary'!F10 -> 10 | L11: =COUNTIFS('Participants-Parties'!$C:$C, A11,'Participants-Parties'!$E:$E, "<>Hopefully Fixed") -> 0 | M11: TRUE | O11: 8 | P11: If party has open issues [COLUMN L], check on them. Update status [Participants tab] if warranted
A12: Uri-Kesh | B12: TRUE | C12: TRUE | D12: TRUE | E12: TRUE | F12: TRUE | G12: TRUE | H12: ='All Party Summary'!B11 -> 8/8 | I12: ='All Party Summary'!C11 -> Yes! | J12: ='All Party Summary'!D11 -> Yes! | K12: ='All Party Summary'!F11 -> 5 | L12: =COUNTIFS('Participants-Parties'!$C:$C, A12,'Participants-Parties'!$E:$E, "<>Hopefully Fixed") -> 1 | M12: TRUE | O12: 9 | P12: Anything else we should know?
A13: Waylon | B13: TRUE | C13: TRUE | D13: TRUE | E13: TRUE | F13: TRUE | G13: TRUE | H13: ='All Party Summary'!B12 -> 8/8 | I13: ='All Party Summary'!C12 -> Yes! | J13: ='All Party Summary'!D12 -> Yes! | K13: ='All Party Summary'!F12 -> 14 | L13: =COUNTIFS('Participants-Parties'!$C:$C, A13,'Participants-Parties'!$E:$E, "<>Hopefully Fixed") -> 0 | M13: FALSE
P14: Saturday Lunch Questions - How's their adventure beginning? Any warning signs?
O15: 1 | P15: It looks like they have/haven't done Cup of Insight yet. [COLUMN I] Is that right?
O16: 2 | P16: It looks like they have/haven't gotten their riddle yet. [COLUMN J] Is that right?
O17: 3 | P17: Have they found their riddle item? [IF SO, CHECK COLUMN M]
O18: 4 | P18: How are they feeling about combat?
O19: 5 | P19: If party has open issues [COLUMN L], check on them. Update status [Participants tab] if warranted
O20: 6 | P20: How is everybody feeling?
O21: 7 | P21: How are people getting along?
O22: 8 | P22: Have they encountered challenges impacting their spirits?
O23: 9 | P23: Does anyone need a personal check in with an EM?
O24: 10 | P24: What can we do to make their experience magical/wonderful?
P26: Saturday Dinner Questions - Roadblocks to finishing? For Saturday night activities?
O27: 1 | P27: Have they found their riddle item? [IF SO, CHECK COLUMN M]
O28: 2 | P28: It looks like they have some/most/all of their party path items. [COLUMN H]. Is that right?
O29: 3 | P29: If party has open issues [COLUMN L], check on them. Update status [Participants tab] if warranted
O30: 4 | P30: Does anyone need a special accommodation for the Saturday night activities? [If so, tell Conductor]
P32: Sunday Breakfast Questions - Clue hammers and the final push
O33: 1 | P33: How are you doing?
O34: 2 | P34: How did everybody sleep?
O35: 3 | P35: How’s everybody feeling this morning?
O36: 4 | P36: Was the Keeper given their vision? Did they share it? Did anyone have thoughts about it?
O37: 5 | P37: It looks like they do/don't have all party path items. [COLUMN H] If they don't, make a plan
O38: 6 | P38: Do they remember when their penultimate meeting is? If not, remind them.
O39: 7 | P39: What if anything are they thinking about their charge?
O40: 8 | P40: Give them the Forcefield Wolven invitation. They can give to party at their discretion.
O41: 9 | P41: Is there anything we can do at the last minute to complete their adventure?

Sheet Combat Log
B3: Chitter 1 | C3: Chitter 2 | D3: Chitter 3 | E3: Skeever 4 | F3: Skeever 5 | G3: Skeever 6 | H3: Skeever 7 | I3: Skeever 8 | J3: Skeever 9 | K3: Skeever 10 | L3: Skeever 11 | M3: Worlog 1 | N3: Worlog 2
A4: Arden
A5: Clairia
A6: Doloron
A7: Elsewhich
A8: Glendeep
A9: Keer
A10: Noctara
A11: P'loa
A12: Sythwan
A13: Uri-Kesh
A14: Waylon
B16: Wolven 1 | C16: Wolven 2 | D16: Wolven 3 | E16: Wolven 4 | F16: Wolven 5 | G16: Wolven 6 | H16: Wolven 7 | I16: Wolven 8 | J16: Wolven 9 | K16: Wolven 10 | L16: Wolven 11 | M16: Wolven 12 | N16: Bachelorette 1 | O16: Bachelorette 2 | Q16: TOTALS
A17: Arden | Q17: Arden | R17: =counta(B4:N4)+counta(B17:O17) -> 0
A18: Clairia | Q18: Clairia | R18: =counta(B5:N5)+counta(B18:O18) -> 0
A19: Doloron | Q19: Doloron | R19: =counta(B6:N6)+counta(B19:O19) -> 0
A20: Elsewhich | Q20: Elsewhich | R20: =counta(B7:N7)+counta(B20:O20) -> 0
A21: Glendeep | Q21: Glendeep | R21: =counta(B8:N8)+counta(B21:O21) -> 0
A22: Keer | Q22: Keer | R22: =counta(B9:N9)+counta(B22:O22) -> 0
A23: Noctara | Q23: Noctara | R23: =counta(B10:N10)+counta(B23:O23) -> 0
A24: P'loa | Q24: P'loa | R24: =counta(B11:N11)+counta(B24:O24) -> 0
A25: Sythwan | Q25: Sythwan | R25: =counta(B12:N12)+counta(B25:O25) -> 0
A26: Uri-Kesh | Q26: Uri-Kesh | R26: =counta(B13:N13)+counta(B26:O26) -> 0
A27: Waylon | Q27: Waylon | R27: =counta(B14:N14)+counta(B27:O27) -> 0

Sheet All Party Summary
B1: Party Path Items | C1: Cup of Insight? | D1: Received Riddle? | E1: Found Riddle Item? | F1: Combats
A2: Arden | B2: =concatenate((countif('Arden_Party Sheet'!A13:A20,"Yes!")),"/8") -> 8/8 | C2: =If('Arden_Party Sheet'!$A$13="Yes!","Yes!","No") -> Yes! | D2: =If('Arden_Party Sheet'!$A$19="Yes!","Yes!","No") -> Yes! | E2: =If(Dashboard!$M3=TRUE,"Yes!","No") -> Yes! | F2: =Combat_Import!V4 -> 9
A3: Clairia | B3: =concatenate((countif('Clairia_Party Sheet'!A13:A20,"Yes!")),"/8") -> 8/8 | C3: =If('Clairia_Party Sheet'!$A$14="Yes!","Yes!","No") -> Yes! | D3: =If('Clairia_Party Sheet'!$A$19="Yes!","Yes!","No") -> Yes! | E3: =If(Dashboard!$M4=TRUE,"Yes!","No") -> No | F3: =Combat_Import!V5 -> 5
A4: Dolorón | B4: =concatenate((countif('Doloron_Party Sheet'!A13:A20,"Yes!")),"/8") -> 7/8 | C4: =If('Doloron_Party Sheet'!$A$16="Yes!","Yes!","No") -> Yes! | D4: =If('Doloron_Party Sheet'!$A$14="Yes!","Yes!","No") -> Yes! | E4: =If(Dashboard!$M5=TRUE,"Yes!","No") -> No | F4: =Combat_Import!V6 -> 7
A5: Elsewhich | B5: =concatenate((countif('Elsewhich_Party Sheet'!A13:A20,"Yes!")),"/8") -> 8/8 | C5: =If('Elsewhich_Party Sheet'!$A$12="Yes!","Yes!","No") -> Yes! | D5: =If('Elsewhich_Party Sheet'!$A$19="Yes!","Yes!","No") -> Yes! | E5: =If(Dashboard!$M6=TRUE,"Yes!","No") -> Yes! | F5: =Combat_Import!V7 -> 7
A6: Glendeep | B6: =concatenate((countif('Glendeep_Party Sheet'!A$13:A$20,"Yes!")),"/8") -> 7/8 | C6: =If('Glendeep_Party Sheet'!$A$12="Yes!","Yes!","No") -> Yes! | D6: =If('Glendeep_Party Sheet'!$A$19="Yes!","Yes!","No") -> Yes! | E6: =If(Dashboard!$M7=TRUE,"Yes!","No") -> Yes! | F6: =Combat_Import!V8 -> 8
A7: Keer | B7: =concatenate((countif('Keer_Party Sheet'!A$13:A$20,"Yes!")),"/8") -> 8/8 | C7: =If('Keer_Party Sheet'!$A$16="Yes!","Yes!","No") -> Yes! | D7: =If('Keer_Party Sheet'!$A$20="Yes!","Yes!","No") -> Yes! | E7: =If(Dashboard!$M8=TRUE,"Yes!","No") -> Yes! | F7: =Combat_Import!V9 -> 9
A8: Noctara | B8: =concatenate((countif('Noctara_Party Sheet'!A$13:A$20,"Yes!")),"/8") -> 8/8 | C8: =If('Noctara_Party Sheet'!$A$15="Yes!","Yes!","No") -> Yes! | D8: =If('Noctara_Party Sheet'!$A$15="Yes!","Yes!","No") -> Yes! | E8: =If(Dashboard!$M9=TRUE,"Yes!","No") -> Yes! | F8: =Combat_Import!V10 -> 8
A9: P'loa | B9: =concatenate((countif('Ploa_Party Sheet'!A$13:A$20,"Yes!")),"/8") -> 8/8 | C9: =If('Ploa_Party Sheet'!$A$16="Yes!","Yes!","No") -> Yes! | D9: =If('Ploa_Party Sheet'!$A$20="Yes!","Yes!","No") -> Yes! | E9: =If(Dashboard!$M10=TRUE,"Yes!","No") -> Yes! | F9: =Combat_Import!V11 -> 8
A10: Sythwan | B10: =concatenate((countif('Sythwan_Party Sheet'!A$13:A$20,"Yes!")),"/8") -> 8/8 | C10: =If('Sythwan_Party Sheet'!$A$16="Yes!","Yes!","No") -> Yes! | D10: =If('Sythwan_Party Sheet'!$A$18="Yes!","Yes!","No") -> Yes! | E10: =If(Dashboard!$M11=TRUE,"Yes!","No") -> Yes! | F10: =Combat_Import!V12 -> 10
A11: Uri-Kesh | B11: =concatenate((countif('UriKesh_Party Sheet'!A$13:A$20,"Yes!")),"/8") -> 8/8 | C11: =If('UriKesh_Party Sheet'!$A$16="Yes!","Yes!","No") -> Yes! | D11: =If('UriKesh_Party Sheet'!$A$14="Yes!","Yes!","No") -> Yes! | E11: =If(Dashboard!$M12=TRUE,"Yes!","No") -> Yes! | F11: =Combat_Import!V13 -> 5
A12: Waylon | B12: =concatenate((countif('Waylon_Party Sheet'!A$13:A$20,"Yes!")),"/8") -> 8/8 | C12: =If('Waylon_Party Sheet'!$A$16="Yes!","Yes!","No") -> Yes! | D12: =If('Waylon_Party Sheet'!$A$16="Yes!","Yes!","No") -> Yes! | E12: =If(Dashboard!$M13=TRUE,"Yes!","No") -> No | F12: =Combat_Import!V14 -> 14
F13: =Combat_Import!O15

Sheet Arden_Party Sheet
A1: ARDEN
A2: Investigating the charge against: Bracken
A3: Companion: Ari (Susan Gerow)
A4: Keeper’s Saturday morning dream: The vision shows the citrine shards and leads the party to Valentina.
A5: Riddle: "laughing girl" fire riddle, fire circle in Winterhill Clearing
A6: Keeper’s Sunday morning dream: This vision shows the Order of the Black Lantern and suggests that it is a club of a different sort than the party (and Bracken) might have originally thought.
A8: Complete? | B8: Staff | C8: Time | D8: Items to give | F8: Complete? | G8: Staff | H8: Info to Give | I8: Bloc Requirements
A9: =if(Arden_Import!B5=true,"Yes!","No") -> Yes! | B9: Aria Morgan | C9: Contact | D9: -- | F9: =if(Arden_Import!B24=true,"Yes!","No") -> Yes! | G9: Angelica Sprink | H9: assigns charge | I9: Need | J9: =COUNTif(F9,"Yes!") -> 1
A10: =if(Arden_Import!B6=true,"Yes!","No") -> Yes! | B10: Ursula Smirch | C10: 2nd Friday | D10: -- | F10: =if(Arden_Import!B25=true,"Yes!","No") -> Yes! | G10: Geneva Sprink | H10: Bracken has been telling Angelica about monsters and that she might get attacked, and suggesting she make a plan to defend herself. (life skills: defense) | I10: Need 5 | J10: =COUNTif(F10:F17,"Yes!") -> 6
A11: =if(Arden_Import!B7=true,"Yes!","No") -> No | B11: Nix Valerius | C11: 3rd Friday | D11: -- | F11: =if(Arden_Import!B26=true,"Yes!","No") -> Yes! | G11: Bartleby Sprink | H11: Bracken has been telling Angelica about how food is made, or how to wash dishes. (life skills: food prep)
A12: =if(Arden_Import!B8=true,"Yes!","No") -> Yes! | B12: Isaiah Cooke | C12: 4th Friday | D12: list of items | F12: =if(Arden_Import!B27=true,"Yes!","No") -> No | G12: Lenora Graves | H12: Bracken has been telling Angelica about monsters and that she might get attacked. (life skills: defense)
A13: =if(Arden_Import!B9=true,"Yes!","No") -> Yes! | B13: Kiko Truthspeaker | C13: 1st Saturday | D13: locus root | F13: =if(Arden_Import!B28=true,"Yes!","No") -> No | G13: Kyson Wayseeker | H13: Angelica never learned basic survival skills, but “a friend” is now teaching her.
A14: =if(Arden_Import!B10=true,"Yes!","No") -> Yes! | B14: Buzzkill | C14: 11am-6pm | D14: none until tomorrow | F14: =if(Arden_Import!B29=true,"Yes!","No") -> Yes! | G14: Samuelson | H14: Angelica has been more independent recently, such as finding out how much her meal costs. (life skills: paying for meals)
A15: =if(Arden_Import!B11=true,"Yes!","No") -> Yes! | B15: Pascal Valerius | C15: 8am-1pm | D15: star of direction | F15: =if(Arden_Import!B30=true,"Yes!","No") -> Yes! | G15: Pansy Golden | H15: Angelica used to be helpless, but recently she seems more self-sufficient (life skills: helping clean).
A16: =if(Arden_Import!B12=true,"Yes!","No") -> Yes! | B16: Karmin Smirch | C16: 9-11am, 1-4pm, 6-8pm | D16: riverglass jewelbox | F16: =if(Arden_Import!B31=true,"Yes!","No") -> Yes! | G16: Kulinos | H16: Angelica used to be helpless, but recently she seems more knowledgeable (life skills: rhubarb leaves are toxic).
A17: =if(Arden_Import!B13=true,"Yes!","No") -> Yes! | B17: Valentina | C17: 10am-4pm | D17: citrine shards | F17: =if(Arden_Import!B32=true,"Yes!","No") -> Yes! | G17: Aleeya Witchborn | H17: Angelica used to be helpless with directions, but Bracken has been teaching her (life skills: understanding directions).
A18: =if(Arden_Import!B14=true,"Yes!","No") -> Yes! | B18: Charlie Peacock | C18: 1-6pm | D18: cowry shell | F18: =if(Arden_Import!B33=true,"Yes!","No") -> Yes! | G18: Karla Smirch | H18: Bracken has given away his belongings to those poorer than himself. | I18: Need | J18: =COUNTif(F18,"Yes!") -> 1
A19: =if(Arden_Import!B15=true,"Yes!","No") -> Yes! | B19: Moxie | C19: 10am-5pm | D19: riddle to argentum heart | F19: =if(Arden_Import!B34=true,"Yes!","No") -> No | G19: Dusty Peacock | H19: Bracken has been hanging around Angelica. But he seems nice and hard to believe he’s harassing her.
A20: =if(Arden_Import!B16=true,"Yes!","No") -> Yes! | B20: Obsidian | C20: 8am-12noon, 2-4pm | D20: spiritstone | F20: =if(Arden_Import!B35=true,"Yes!","No") -> Yes! | G20: Phineas Smirch | H20: Bracken is a thug and a menace. Born bad. | I20: Need 2 | J20: =COUNTif(F20:F22,"Yes!") -> 2
A21: =if(Arden_Import!B17=true,"Yes!","No") -> Yes! | B21: Ghost Theater | C21: 4-8pm | D21: limelight | F21: =if(Arden_Import!B36=true,"Yes!","No") -> No | G21: Equinoxious | H21: Bracken had a rough childhood. He’s learned many survival skills, including questionable ones like lock-picking. May be trouble.
A22: =if(Arden_Import!B18=true,"Yes!","No") -> No | B22: Buzzkill | C22: 9:45am Sunday | D22: chaos pendant | F22: =if(Arden_Import!B37=true,"Yes!","No") -> Yes! | G22: Isaiah Cooke | H22: Bracken had a rough childhood. He’s been seen walking near the wildlands. May be trouble.
A23: =if(Arden_Import!B19=true,"Yes!","No") -> No | B23: Morgoth & Henchmen | C23: 10am Sunday | D23: Sconce of the Wood | F23: =if(Arden_Import!B38=true,"Yes!","No") -> Yes! | G23: Crabtree | H23: Crown of St. Mora, which was stolen several years ago, was anonymously left at the Valerius house a couple weeks ago. | I23: Need 1 | J23: =COUNTif(F23:F24,"Yes!") -> 2
A24: =If(Dashboard!$M3=TRUE,"Yes!","No") -> Yes! | B24: riddle item found? | C24: -- | D24: -- | F24: =if(Arden_Import!B39=true,"Yes!","No") -> Yes! | G24: Aesthetika | H24: Crown of St. Mora, which was stolen several years ago, was anonymously left at the Valerius house a couple weeks ago.
F25: =if(Arden_Import!B40=true,"Yes!","No") -> Yes! | G25: Santiago Valerius | H25: Bracken is the person who left the Crown of St. Mora at the Valerius house. But why did he have it? | I25: Need | J25: =COUNTif(F25,"Yes!") -> 1
A26: COMMENTS | F26: =if(Arden_Import!B41=true,"Yes!","No") -> Yes! | G26: Dimitri | H26: Rumor that Smirches had the Crown of St. Mora, although no idea why they had it or would return it. | I26: Need 1 | J26: =COUNTif(F26:F27,"Yes!") -> 1
A27: =IFERROR(__xludf.DUMMYFUNCTION("IFERROR( FILTER( FLATTEN({Arden_Import!C5:C20; Arden_Import!C24:C52; Arden_Import!A55:A79}), FLATTEN({Arden_Import!C5:C20; Arden_Import!C24:C52; Arden_Import!A55:A79}) <> """" ), """" )"),"Spoke with Birdie, Starling, & Willow- discussed Memory Lapse from last night, theater burning, and Golden Page/Nemaiah. Party was ""hesitant to trust others"" but they opened up after some conversation. Introduced to Ursula. DG") -> Spoke with Birdie, Starling, & Willow- discussed Memory Lapse from last night, theater burning, and Golden Page/Nemaiah. Party was "hesitant to trust others" but they opened up after some conversation. Introduced to Ursula. DG | F27: =if(Arden_Import!B42=true,"Yes!","No") -> No | G27: Fenwick Michaels | H27: Rumor that a merchant family in WE had the Crown of St. Mora. No idea how/why it was returned.
A28: =IFERROR(__xludf.DUMMYFUNCTION("""COMPUTED_VALUE"""),"Gave them the list Friday night (sorry, put in the wrong cell)") -> Gave them the list Friday night (sorry, put in the wrong cell) | F28: =if(Arden_Import!B43=true,"Yes!","No") -> Yes! | G28: Bracken | H28: Barring truth magic, he’s not sure what the party is talking about and/or Left the Crown
A29: =IFERROR(__xludf.DUMMYFUNCTION("""COMPUTED_VALUE"""),"Traveler had not shared the list with the group, got her to share lore, and some of the list, but fewer people heard that. 10:30.") -> Traveler had not shared the list with the group, got her to share lore, and some of the list, but fewer people heard that. 10:30. | F29: =if(Arden_Import!B44=true,"Yes!","No") -> Yes! | G29: Pearl Bryce | H29: Bracken asked if dragons were real. They’re not. | I29: Need 1 | J29: =COUNTif(F29:F30,"Yes!") -> 2
A30: =IFERROR(__xludf.DUMMYFUNCTION("""COMPUTED_VALUE"""),"Did challenge with them, will give on Sunday at the coordinator's leisure (AS)") -> Did challenge with them, will give on Sunday at the coordinator's leisure (AS) | F30: =if(Arden_Import!B45=true,"Yes!","No") -> Yes! | G30: Kora Peacekeeper | H30: Bracken asked if dragons were real. They’re not.
A31: =IFERROR(__xludf.DUMMYFUNCTION("""COMPUTED_VALUE"""),"Finished the jingle challenge with them at 4pm on Saturday. I'm sure nothing horrible happened right as I walked away. -DaveKamin") -> Finished the jingle challenge with them at 4pm on Saturday. I'm sure nothing horrible happened right as I walked away. -DaveKamin | F31: =if(Arden_Import!B46=true,"Yes!","No") -> Yes! | G31: Tinker Bill | H31: Tinker Bill found “Ever Vigilant * Ever Fabulous” coasters propping up a table; Solomon & Bonnie said they’re not theirs. The party should keep some! | I31: Need | J31: =COUNTif(F31,"Yes!") -> 1
A32: =IFERROR(__xludf.DUMMYFUNCTION("""COMPUTED_VALUE"""),"Switched to pitch pipe challenge and did it in front of tavern after their ghost theater in Charlie's absence. -JF") -> Switched to pitch pipe challenge and did it in front of tavern after their ghost theater in Charlie's absence. -JF | F32: =if(Arden_Import!B47=true,"Yes!","No") -> Yes! | G32: Kyli Talespinner | H32: Bracken dropped a piece of black paper. She’s hoping the party can help figure it out. The paper lists quests, with the final one partially ripped away. | I32: Need | J32: =COUNTif(F32,"Yes!") -> 1
A33: =IFERROR(__xludf.DUMMYFUNCTION("""COMPUTED_VALUE"""),"Found them at 6pm. Petulantly threw the stupid riddle at them. -LN") -> Found them at 6pm. Petulantly threw the stupid riddle at them. -LN | F33: =if(Dashboard!G3=true,"Yes!","No") -> Yes! | G33: Keeper’s Sunday Vision | H33: Shows the Order of the Black Lantern and suggests that it is a club of a different sort than the party (and Bracken) might have originally thought. | I33: Need | J33: =COUNTif(F33,"Yes!") -> 1
A34: =IFERROR(__xludf.DUMMYFUNCTION("""COMPUTED_VALUE"""),"Did a bit of a ""who cares speedrun"" but had a good experience. -Dave Nadig") -> Did a bit of a "who cares speedrun" but had a good experience. -Dave Nadig | F34: =if(Arden_Import!B49=true,"Yes!","No") -> No | G34: Angelica Sprink | H34: Angelica was attacked by wolven, but Bracken’s training let her fend them off. | I34: Need | J34: =COUNTif(F34,"Yes!") -> 0
A35: =IFERROR(__xludf.DUMMYFUNCTION("""COMPUTED_VALUE"""),"Met them in preperation to assign charge LD, assigned charge with a side of tears and teenage angst.") -> Met them in preperation to assign charge LD, assigned charge with a side of tears and teenage angst. | F35: =if(Arden_Import!B50=true,"Yes!","No") -> No | G35: Bracken | H35: Bracken reveals details about the order and quests. | I35: Need | J35: =COUNTif(F35,"Yes!") -> 0
A36: =IFERROR(__xludf.DUMMYFUNCTION("""COMPUTED_VALUE"""),"Did not directly approach but sat next to them at lunch and was told they already fully understood charge from overhearing Angelica and Geneva fight and not to clue hammer any more ") -> Did not directly approach but sat next to them at lunch and was told they already fully understood charge from overhearing Angelica and Geneva fight and not to clue hammer any more | F36: =if(Arden_Import!B51=true,"Yes!","No") -> No | G36: Karmin Smirch | H36: Has a new set of clothing that is Bracken’s size. The party will help him acquire it. | I36: Need | J36: =COUNTif(F36,"Yes!") -> 0
A37: =IFERROR(__xludf.DUMMYFUNCTION("""COMPUTED_VALUE"""),"Was told they already had info they needed, not to clue hammer them") -> Was told they already had info they needed, not to clue hammer them | F37: =if(Arden_Import!B52=true,"Yes!","No") -> No | G37: Adina Valerius | H37: Bracken is attempting to join a secretive order of knights. Since one of his missions requires that he rescue a damsel in distress, Bracken has interpreted this to mean he should teach the helpless Angelica Sprink the life skills she was lacking, and this, as well as the other quests he is in the process of completing, explain his potentially questionable behavior. Although Bracken doesn’t yet know how special and unusual this particular order is, he’ll ultimately be deemed worthy of entry into this secretive and fabulous Knight Club. | I37: Need | J37: =COUNTif(F37,"Yes!") -> 0
A38: =IFERROR(__xludf.DUMMYFUNCTION("""COMPUTED_VALUE"""),"Talked to woman in light green shirt. Two others listened.") -> Talked to woman in light green shirt. Two others listened.
A39: =IFERROR(__xludf.DUMMYFUNCTION("""COMPUTED_VALUE"""),"Sat night during apple crisp. They asked about a Black Lamp secret society, I said I didn't know anything about that.") -> Sat night during apple crisp. They asked about a Black Lamp secret society, I said I didn't know anything about that.
A40: =IFERROR(__xludf.DUMMYFUNCTION("""COMPUTED_VALUE"""),"Slipped the info in as a natural aside at breakfast to two participants on the periphery just after they spoke with Samuelson about Angelica, and before Bartleby came over to them. Very interested. ") -> Slipped the info in as a natural aside at breakfast to two participants on the periphery just after they spoke with Samuelson about Angelica, and before Bartleby came over to them. Very interested.
A41: =IFERROR(__xludf.DUMMYFUNCTION("""COMPUTED_VALUE"""),"3 of the party members were very focused on the info and then tried to teach Karla the magic of giving to help her better understand Bracken") -> 3 of the party members were very focused on the info and then tried to teach Karla the magic of giving to help her better understand Bracken
...

Sheet Combat_Import
A1: =IFERROR(__xludf.DUMMYFUNCTION("IMPORTRANGE(""https://docs.google.com/spreadsheets/d/1PPFix0KE5FV0_ekB8X93l4fBTTlhI3_4FnP7klgfg_Y/edit?gid=0#gid=0"", ""Combat!a1:z30"")"),"") | B1: =IFERROR(__xludf.DUMMYFUNCTION("""COMPUTED_VALUE"""),"Arden") -> Arden | C1: =IFERROR(__xludf.DUMMYFUNCTION("""COMPUTED_VALUE"""),"Clairia") -> Clairia | D1: =IFERROR(__xludf.DUMMYFUNCTION("""COMPUTED_VALUE"""),"Doloron") -> Doloron | E1: =IFERROR(__xludf.DUMMYFUNCTION("""COMPUTED_VALUE"""),"Elsewhich") -> Elsewhich | F1: =IFERROR(__xludf.DUMMYFUNCTION("""COMPUTED_VALUE"""),"Glendeep") -> Glendeep | G1: =IFERROR(__xludf.DUMMYFUNCTION("""COMPUTED_VALUE"""),"Keer") -> Keer | H1: =IFERROR(__xludf.DUMMYFUNCTION("""COMPUTED_VALUE"""),"Noctara") -> Noctara | I1: =IFERROR(__xludf.DUMMYFUNCTION("""COMPUTED_VALUE"""),"P'loa") -> P'loa | J1: =IFERROR(__xludf.DUMMYFUNCTION("""COMPUTED_VALUE"""),"Sythwan") -> Sythwan | K1: =IFERROR(__xludf.DUMMYFUNCTION("""COMPUTED_VALUE"""),"Uri-Kesh") -> Uri-Kesh | L1: =IFERROR(__xludf.DUMMYFUNCTION("""COMPUTED_VALUE"""),"Waylon") -> Waylon | M1: =IFERROR(__xludf.DUMMYFUNCTION("""COMPUTED_VALUE"""),"Notes") -> Notes
A2: =IFERROR(__xludf.DUMMYFUNCTION("""COMPUTED_VALUE"""),"Chitter 1") -> Chitter 1 | B2: =IFERROR(__xludf.DUMMYFUNCTION("""COMPUTED_VALUE"""),TRUE) -> TRUE | C2: =IFERROR(__xludf.DUMMYFUNCTION("""COMPUTED_VALUE"""),TRUE) -> TRUE | D2: =IFERROR(__xludf.DUMMYFUNCTION("""COMPUTED_VALUE"""),TRUE) -> TRUE | E2: =IFERROR(__xludf.DUMMYFUNCTION("""COMPUTED_VALUE"""),FALSE) -> FALSE | F2: =IFERROR(__xludf.DUMMYFUNCTION("""COMPUTED_VALUE"""),TRUE) -> TRUE | G2: =IFERROR(__xludf.DUMMYFUNCTION("""COMPUTED_VALUE"""),TRUE) -> TRUE | H2: =IFERROR(__xludf.DUMMYFUNCTION("""COMPUTED_VALUE"""),FALSE) -> FALSE | I2: =IFERROR(__xludf.DUMMYFUNCTION("""COMPUTED_VALUE"""),FALSE) -> FALSE | J2: =IFERROR(__xludf.DUMMYFUNCTION("""COMPUTED_VALUE"""),FALSE) -> FALSE | K2: =IFERROR(__xludf.DUMMYFUNCTION("""COMPUTED_VALUE"""),FALSE) -> FALSE | L2: =IFERROR(__xludf.DUMMYFUNCTION("""COMPUTED_VALUE"""),FALSE) -> FALSE | M2: =IFERROR(__xludf.DUMMYFUNCTION("""COMPUTED_VALUE"""),"Arden, Doloron, and Keer hit the chitters as a single group and got one bag between them. Elsewhich met us right after Claria and did not have pre-breakfast combat. All rangers were right on the soothing chitters function. (GR - 7AM)") -> Arden, Doloron, and Keer hit the chitters as a single group and got one bag between them. Elsewhich met us right after Claria and did not have pre-breakfast combat. All rangers were right on the soothing chitters function. (GR - 7AM)
A3: =IFERROR(__xludf.DUMMYFUNCTION("""COMPUTED_VALUE"""),"Chitter 2") -> Chitter 2 | B3: =IFERROR(__xludf.DUMMYFUNCTION("""COMPUTED_VALUE"""),FALSE) -> FALSE | C3: =IFERROR(__xludf.DUMMYFUNCTION("""COMPUTED_VALUE"""),FALSE) -> FALSE | D3: =IFERROR(__xludf.DUMMYFUNCTION("""COMPUTED_VALUE"""),FALSE) -> FALSE | E3: =IFERROR(__xludf.DUMMYFUNCTION("""COMPUTED_VALUE"""),FALSE) -> FALSE | F3: =IFERROR(__xludf.DUMMYFUNCTION("""COMPUTED_VALUE"""),FALSE) -> FALSE | G3: =IFERROR(__xludf.DUMMYFUNCTION("""COMPUTED_VALUE"""),FALSE) -> FALSE | H3: =IFERROR(__xludf.DUMMYFUNCTION("""COMPUTED_VALUE"""),FALSE) -> FALSE | I3: =IFERROR(__xludf.DUMMYFUNCTION("""COMPUTED_VALUE"""),FALSE) -> FALSE | ... L3: =IFERROR(__xludf.DUMMYFUNCTION("""COMPUTED_VALUE"""),FALSE) -> FALSE | U3: =IFERROR(__xludf.DUMMYFUNCTION("""COMPUTED_VALUE"""),"TOTALS") -> TOTALS
A4: =IFERROR(__xludf.DUMMYFUNCTION("""COMPUTED_VALUE"""),"Chitter 3") -> Chitter 3 | B4: =IFERROR(__xludf.DUMMYFUNCTION("""COMPUTED_VALUE"""),FALSE) -> FALSE | C4: =IFERROR(__xludf.DUMMYFUNCTION("""COMPUTED_VALUE"""),TRUE) -> TRUE | D4: =IFERROR(__xludf.DUMMYFUNCTION("""COMPUTED_VALUE"""),FALSE) -> FALSE | E4: =IFERROR(__xludf.DUMMYFUNCTION("""COMPUTED_VALUE"""),FALSE) -> FALSE | F4: =IFERROR(__xludf.DUMMYFUNCTION("""COMPUTED_VALUE"""),FALSE) -> FALSE | G4: =IFERROR(__xludf.DUMMYFUNCTION("""COMPUTED_VALUE"""),FALSE) -> FALSE | H4: =IFERROR(__xludf.DUMMYFUNCTION("""COMPUTED_VALUE"""),TRUE) -> TRUE | I4: =IFERROR(__xludf.DUMMYFUNCTION("""COMPUTED_VALUE"""),FALSE) -> FALSE | J4: =IFERROR(__xludf.DUMMYFUNCTION("""COMPUTED_VALUE"""),TRUE) -> TRUE | K4: =IFERROR(__xludf.DUMMYFUNCTION("""COMPUTED_VALUE"""),TRUE) -> TRUE | L4: =IFERROR(__xludf.DUMMYFUNCTION("""COMPUTED_VALUE"""),FALSE) -> FALSE | M4: =IFERROR(__xludf.DUMMYFUNCTION("""COMPUTED_VALUE"""),"Fought Sythwan twice. They used soothing once and move in shadows once. Uri-Kesh and Clairia fought chitters together.") -> Fought Sythwan twice. They used soothing once and move in shadows once. Uri-Kesh and Clairia fought chitters together. | U4: =IFERROR(__xludf.DUMMYFUNCTION("""COMPUTED_VALUE"""),"Arden") -> Arden | V4: =IFERROR(__xludf.DUMMYFUNCTION("""COMPUTED_VALUE"""),9.0) -> 9
A5: =IFERROR(__xludf.DUMMYFUNCTION("""COMPUTED_VALUE"""),"Skeever 4") -> Skeever 4 | B5: =IFERROR(__xludf.DUMMYFUNCTION("""COMPUTED_VALUE"""),FALSE) -> FALSE | C5: =IFERROR(__xludf.DUMMYFUNCTION("""COMPUTED_VALUE"""),FALSE) -> FALSE | D5: =IFERROR(__xludf.DUMMYFUNCTION("""COMPUTED_VALUE"""),FALSE) -> FALSE | E5: =IFERROR(__xludf.DUMMYFUNCTION("""COMPUTED_VALUE"""),FALSE) -> FALSE | F5: =IFERROR(__xludf.DUMMYFUNCTION("""COMPUTED_VALUE"""),FALSE) -> FALSE | G5: =IFERROR(__xludf.DUMMYFUNCTION("""COMPUTED_VALUE"""),FALSE) -> FALSE | H5: =IFERROR(__xludf.DUMMYFUNCTION("""COMPUTED_VALUE"""),FALSE) -> FALSE | I5: =IFERROR(__xludf.DUMMYFUNCTION("""COMPUTED_VALUE"""),FALSE) -> FALSE | J5: =IFERROR(__xludf.DUMMYFUNCTION("""COMPUTED_VALUE"""),TRUE) -> TRUE | K5: =IFERROR(__xludf.DUMMYFUNCTION("""COMPUTED_VALUE"""),FALSE) -> FALSE | L5: =IFERROR(__xludf.DUMMYFUNCTION("""COMPUTED_VALUE"""),TRUE) -> TRUE | M5: =IFERROR(__xludf.DUMMYFUNCTION("""COMPUTED_VALUE"""),"Pre-breakfast encountered Waylon and Sythwan together - gave them 1 pouch. Then encountered Sythwan after breakfast - they used Swampfoot") -> Pre-breakfast encountered Waylon and Sythwan together - gave them 1 pouch. Then encountered Sythwan after breakfast - they used Swampfoot | U5: =IFERROR(__xludf.DUMMYFUNCTION("""COMPUTED_VALUE"""),"Clairia") -> Clairia | V5: =IFERROR(__xludf.DUMMYFUNCTION("""COMPUTED_VALUE"""),5.0) -> 5
A6: =IFERROR(__xludf.DUMMYFUNCTION("""COMPUTED_VALUE"""),"Skeever 5") -> Skeever 5 | B6: =IFERROR(__xludf.DUMMYFUNCTION("""COMPUTED_VALUE"""),FALSE) -> FALSE | C6: =IFERROR(__xludf.DUMMYFUNCTION("""COMPUTED_VALUE"""),FALSE) -> FALSE | D6: =IFERROR(__xludf.DUMMYFUNCTION("""COMPUTED_VALUE"""),FALSE) -> FALSE | E6: =IFERROR(__xludf.DUMMYFUNCTION("""COMPUTED_VALUE"""),TRUE) -> TRUE | F6: =IFERROR(__xludf.DUMMYFUNCTION("""COMPUTED_VALUE"""),FALSE) -> FALSE | G6: =IFERROR(__xludf.DUMMYFUNCTION("""COMPUTED_VALUE"""),TRUE) -> TRUE | H6: =IFERROR(__xludf.DUMMYFUNCTION("""COMPUTED_VALUE"""),TRUE) -> TRUE | I6: =IFERROR(__xludf.DUMMYFUNCTION("""COMPUTED_VALUE"""),FALSE) -> FALSE | J6: =IFERROR(__xludf.DUMMYFUNCTION("""COMPUTED_VALUE"""),FALSE) -> FALSE | K6: =IFERROR(__xludf.DUMMYFUNCTION("""COMPUTED_VALUE"""),FALSE) -> FALSE | L6: =IFERROR(__xludf.DUMMYFUNCTION("""COMPUTED_VALUE"""),TRUE) -> TRUE | M6: =IFERROR(__xludf.DUMMYFUNCTION("""COMPUTED_VALUE"""),"Noctara has stookesters' (they cast Turn Coat); then teamed up with Skeever 7 to get G, W & E (U avoided us)") -> Noctara has stookesters' (they cast Turn Coat); then teamed up with Skeever 7 to get G, W & E (U avoided us) | U6: =IFERROR(__xludf.DUMMYFUNCTION("""COMPUTED_VALUE"""),"Doloron") -> Doloron | V6: =IFERROR(__xludf.DUMMYFUNCTION("""COMPUTED_VALUE"""),7.0) -> 7
A7: =IFERROR(__xludf.DUMMYFUNCTION("""COMPUTED_VALUE"""),"Skeever 6") -> Skeever 6 | B7: =IFERROR(__xludf.DUMMYFUNCTION("""COMPUTED_VALUE"""),FALSE) -> FALSE | C7: =IFERROR(__xludf.DUMMYFUNCTION("""COMPUTED_VALUE"""),FALSE) -> FALSE | D7: =IFERROR(__xludf.DUMMYFUNCTION("""COMPUTED_VALUE"""),FALSE) -> FALSE | E7: =IFERROR(__xludf.DUMMYFUNCTION("""COMPUTED_VALUE"""),FALSE) -> FALSE | F7: =IFERROR(__xludf.DUMMYFUNCTION("""COMPUTED_VALUE"""),FALSE) -> FALSE | G7: =IFERROR(__xludf.DUMMYFUNCTION("""COMPUTED_VALUE"""),FALSE) -> FALSE | H7: =IFERROR(__xludf.DUMMYFUNCTION("""COMPUTED_VALUE"""),FALSE) -> FALSE | I7: =IFERROR(__xludf.DUMMYFUNCTION("""COMPUTED_VALUE"""),FALSE) -> FALSE | ... L7: =IFERROR(__xludf.DUMMYFUNCTION("""COMPUTED_VALUE"""),FALSE) -> FALSE | U7: =IFERROR(__xludf.DUMMYFUNCTION("""COMPUTED_VALUE"""),"Elsewhich") -> Elsewhich | V7: =IFERROR(__xludf.DUMMYFUNCTION("""COMPUTED_VALUE"""),7.0) -> 7
A8: =IFERROR(__xludf.DUMMYFUNCTION("""COMPUTED_VALUE"""),"Skeever 7") -> Skeever 7 | B8: =IFERROR(__xludf.DUMMYFUNCTION("""COMPUTED_VALUE"""),FALSE) -> FALSE | C8: =IFERROR(__xludf.DUMMYFUNCTION("""COMPUTED_VALUE"""),FALSE) -> FALSE | D8: =IFERROR(__xludf.DUMMYFUNCTION("""COMPUTED_VALUE"""),FALSE) -> FALSE | E8: =IFERROR(__xludf.DUMMYFUNCTION("""COMPUTED_VALUE"""),TRUE) -> TRUE | F8: =IFERROR(__xludf.DUMMYFUNCTION("""COMPUTED_VALUE"""),FALSE) -> FALSE | G8: =IFERROR(__xludf.DUMMYFUNCTION("""COMPUTED_VALUE"""),TRUE) -> TRUE | H8: =IFERROR(__xludf.DUMMYFUNCTION("""COMPUTED_VALUE"""),TRUE) -> TRUE | I8: =IFERROR(__xludf.DUMMYFUNCTION("""COMPUTED_VALUE"""),TRUE) -> TRUE | J8: =IFERROR(__xludf.DUMMYFUNCTION("""COMPUTED_VALUE"""),FALSE) -> FALSE | K8: =IFERROR(__xludf.DUMMYFUNCTION("""COMPUTED_VALUE"""),FALSE) -> FALSE | L8: =IFERROR(__xludf.DUMMYFUNCTION("""COMPUTED_VALUE"""),TRUE) -> TRUE | M8: =IFERROR(__xludf.DUMMYFUNCTION("""COMPUTED_VALUE"""),"Everything was with skeever 5 except P'loa, who cast whirlwind on us.") -> Everything was with skeever 5 except P'loa, who cast whirlwind on us. | U8: =IFERROR(__xludf.DUMMYFUNCTION("""COMPUTED_VALUE"""),"Glendeep") -> Glendeep | V8: =IFERROR(__xludf.DUMMYFUNCTION("""COMPUTED_VALUE"""),8.0) -> 8
A9: =IFERROR(__xludf.DUMMYFUNCTION("""COMPUTED_VALUE"""),"Skeever 8") -> Skeever 8 | B9: =IFERROR(__xludf.DUMMYFUNCTION("""COMPUTED_VALUE"""),FALSE) -> FALSE | C9: =IFERROR(__xludf.DUMMYFUNCTION("""COMPUTED_VALUE"""),FALSE) -> FALSE | D9: =IFERROR(__xludf.DUMMYFUNCTION("""COMPUTED_VALUE"""),FALSE) -> FALSE | E9: =IFERROR(__xludf.DUMMYFUNCTION("""COMPUTED_VALUE"""),TRUE) -> TRUE | F9: =IFERROR(__xludf.DUMMYFUNCTION("""COMPUTED_VALUE"""),FALSE) -> FALSE | G9: =IFERROR(__xludf.DUMMYFUNCTION("""COMPUTED_VALUE"""),TRUE) -> TRUE | H9: =IFERROR(__xludf.DUMMYFUNCTION("""COMPUTED_VALUE"""),FALSE) -> FALSE | I9: =IFERROR(__xludf.DUMMYFUNCTION("""COMPUTED_VALUE"""),FALSE) -> FALSE | J9: =IFERROR(__xludf.DUMMYFUNCTION("""COMPUTED_VALUE"""),TRUE) -> TRUE | K9: =IFERROR(__xludf.DUMMYFUNCTION("""COMPUTED_VALUE"""),FALSE) -> FALSE | L9: =IFERROR(__xludf.DUMMYFUNCTION("""COMPUTED_VALUE"""),TRUE) -> TRUE | M9: =IFERROR(__xludf.DUMMYFUNCTION("""COMPUTED_VALUE"""),"Sythwan used gravitational pull; seemed inclined to leave us alone (having looted the third member). They also hit Cursed Skeever right after us, I think, so they may be (a) rich or (b) damaged. -LN, noon") -> Sythwan used gravitational pull; seemed inclined to leave us alone (having looted the third member). They also hit Cursed Skeever right after us, I think, so they may be (a) rich or (b) damaged. -LN, noon | U9: =IFERROR(__xludf.DUMMYFUNCTION("""COMPUTED_VALUE"""),"Keer") -> Keer | V9: =IFERROR(__xludf.DUMMYFUNCTION("""COMPUTED_VALUE"""),9.0) -> 9
A10: =IFERROR(__xludf.DUMMYFUNCTION("""COMPUTED_VALUE"""),"Skeever 9") -> Skeever 9 | B10: =IFERROR(__xludf.DUMMYFUNCTION("""COMPUTED_VALUE"""),TRUE) -> TRUE | C10: =IFERROR(__xludf.DUMMYFUNCTION("""COMPUTED_VALUE"""),FALSE) -> FALSE | D10: =IFERROR(__xludf.DUMMYFUNCTION("""COMPUTED_VALUE"""),TRUE) -> TRUE | E10: =IFERROR(__xludf.DUMMYFUNCTION("""COMPUTED_VALUE"""),FALSE) -> FALSE | F10: =IFERROR(__xludf.DUMMYFUNCTION("""COMPUTED_VALUE"""),TRUE) -> TRUE | G10: =IFERROR(__xludf.DUMMYFUNCTION("""COMPUTED_VALUE"""),FALSE) -> FALSE | H10: =IFERROR(__xludf.DUMMYFUNCTION("""COMPUTED_VALUE"""),FALSE) -> FALSE | I10: =IFERROR(__xludf.DUMMYFUNCTION("""COMPUTED_VALUE"""),TRUE) -> TRUE | J10: =IFERROR(__xludf.DUMMYFUNCTION("""COMPUTED_VALUE"""),FALSE) -> FALSE | K10: =IFERROR(__xludf.DUMMYFUNCTION("""COMPUTED_VALUE"""),FALSE) -> FALSE | L10: =IFERROR(__xludf.DUMMYFUNCTION("""COMPUTED_VALUE"""),TRUE) -> TRUE | M10: =IFERROR(__xludf.DUMMYFUNCTION("""COMPUTED_VALUE"""),"p'loa and waylon used death,arden rootfoot, doloron wirlwind,glendeep gravitational pull,teleport other, frost bite. A number of hits from cursed skeever dealt out to all parties (and usually some healing needed). Arden has at least one or two very tactic"&"ally impressive fighters. Would love if cursed wolven was able to hit P'loa again, the keeper really struggled and I would love for them to get a second chance to possibly step up more.") -> p'loa and waylon used death,arden rootfoot, doloron wirlwind,glendeep gravitational pull,teleport other, frost bite. A number of hits from cursed skeever dealt out to all parties (and usually some healing needed). Arden has at least one or two very tactically impressive fighters. Would love if cursed wolven was able to hit P'loa again, the keeper really struggled and I would love for them to get a second chance to possibly step up more. | U10: =IFERROR(__xludf.DUMMYFUNCTION("""COMPUTED_VALUE"""),"Noctara") -> Noctara | V10: =IFERROR(__xludf.DUMMYFUNCTION("""COMPUTED_VALUE"""),8.0) -> 8
A11: =IFERROR(__xludf.DUMMYFUNCTION("""COMPUTED_VALUE"""),"Skeever 10") -> Skeever 10 | B11: =IFERROR(__xludf.DUMMYFUNCTION("""COMPUTED_VALUE"""),FALSE) -> FALSE | C11: =IFERROR(__xludf.DUMMYFUNCTION("""COMPUTED_VALUE"""),FALSE) -> FALSE | D11: =IFERROR(__xludf.DUMMYFUNCTION("""COMPUTED_VALUE"""),TRUE) -> TRUE | E11: =IFERROR(__xludf.DUMMYFUNCTION("""COMPUTED_VALUE"""),FALSE) -> FALSE | F11: =IFERROR(__xludf.DUMMYFUNCTION("""COMPUTED_VALUE"""),FALSE) -> FALSE | G11: =IFERROR(__xludf.DUMMYFUNCTION("""COMPUTED_VALUE"""),FALSE) -> FALSE | H11: =IFERROR(__xludf.DUMMYFUNCTION("""COMPUTED_VALUE"""),FALSE) -> FALSE | I11: =IFERROR(__xludf.DUMMYFUNCTION("""COMPUTED_VALUE"""),FALSE) -> FALSE | J11: =IFERROR(__xludf.DUMMYFUNCTION("""COMPUTED_VALUE"""),TRUE) -> TRUE | K11: =IFERROR(__xludf.DUMMYFUNCTION("""COMPUTED_VALUE"""),TRUE) -> TRUE | L11: =IFERROR(__xludf.DUMMYFUNCTION("""COMPUTED_VALUE"""),FALSE) -> FALSE | M11: =IFERROR(__xludf.DUMMYFUNCTION("""COMPUTED_VALUE"""),"Sythwan used frost spell, UriKesh used two spells and thanked us for the fight, Doloron used sleep spell and thanked us") -> Sythwan used frost spell, UriKesh used two spells and thanked us for the fight, Doloron used sleep spell and thanked us | U11: =IFERROR(__xludf.DUMMYFUNCTION("""COMPUTED_VALUE"""),"P'loa") -> P'loa | V11: =IFERROR(__xludf.DUMMYFUNCTION("""COMPUTED_VALUE"""),8.0) -> 8
A12: =IFERROR(__xludf.DUMMYFUNCTION("""COMPUTED_VALUE"""),"Skeever 11") -> Skeever 11 | B12: =IFERROR(__xludf.DUMMYFUNCTION("""COMPUTED_VALUE"""),FALSE) -> FALSE | C12: =IFERROR(__xludf.DUMMYFUNCTION("""COMPUTED_VALUE"""),TRUE) -> TRUE | D12: =IFERROR(__xludf.DUMMYFUNCTION("""COMPUTED_VALUE"""),FALSE) -> FALSE | E12: =IFERROR(__xludf.DUMMYFUNCTION("""COMPUTED_VALUE"""),TRUE) -> TRUE | F12: =IFERROR(__xludf.DUMMYFUNCTION("""COMPUTED_VALUE"""),TRUE) -> TRUE | G12: =IFERROR(__xludf.DUMMYFUNCTION("""COMPUTED_VALUE"""),TRUE) -> TRUE | H12: =IFERROR(__xludf.DUMMYFUNCTION("""COMPUTED_VALUE"""),FALSE) -> FALSE | I12: =IFERROR(__xludf.DUMMYFUNCTION("""COMPUTED_VALUE"""),FALSE) -> FALSE | J12: =IFERROR(__xludf.DUMMYFUNCTION("""COMPUTED_VALUE"""),FALSE) -> FALSE | K12: =IFERROR(__xludf.DUMMYFUNCTION("""COMPUTED_VALUE"""),FALSE) -> FALSE | L12: =IFERROR(__xludf.DUMMYFUNCTION("""COMPUTED_VALUE"""),FALSE) -> FALSE | U12: =IFERROR(__xludf.DUMMYFUNCTION("""COMPUTED_VALUE"""),"Sythwan") -> Sythwan | V12: =IFERROR(__xludf.DUMMYFUNCTION("""COMPUTED_VALUE"""),10.0) -> 10
A13: =IFERROR(__xludf.DUMMYFUNCTION("""COMPUTED_VALUE"""),"Worlog 1") -> Worlog 1 | B13: =IFERROR(__xludf.DUMMYFUNCTION("""COMPUTED_VALUE"""),TRUE) -> TRUE | C13: =IFERROR(__xludf.DUMMYFUNCTION("""COMPUTED_VALUE"""),FALSE) -> FALSE | D13: =IFERROR(__xludf.DUMMYFUNCTION("""COMPUTED_VALUE"""),TRUE) -> TRUE | E13: =IFERROR(__xludf.DUMMYFUNCTION("""COMPUTED_VALUE"""),FALSE) -> FALSE | F13: =IFERROR(__xludf.DUMMYFUNCTION("""COMPUTED_VALUE"""),TRUE) -> TRUE | G13: =IFERROR(__xludf.DUMMYFUNCTION("""COMPUTED_VALUE"""),TRUE) -> TRUE | H13: =IFERROR(__xludf.DUMMYFUNCTION("""COMPUTED_VALUE"""),FALSE) -> FALSE | I13: =IFERROR(__xludf.DUMMYFUNCTION("""COMPUTED_VALUE"""),TRUE) -> TRUE | J13: =IFERROR(__xludf.DUMMYFUNCTION("""COMPUTED_VALUE"""),TRUE) -> TRUE | K13: =IFERROR(__xludf.DUMMYFUNCTION("""COMPUTED_VALUE"""),TRUE) -> TRUE | L13: =IFERROR(__xludf.DUMMYFUNCTION("""COMPUTED_VALUE"""),TRUE) -> TRUE | U13: =IFERROR(__xludf.DUMMYFUNCTION("""COMPUTED_VALUE"""),"Uri-Kesh") -> Uri-Kesh | V13: =IFERROR(__xludf.DUMMYFUNCTION("""COMPUTED_VALUE"""),5.0) -> 5
A14: =IFERROR(__xludf.DUMMYFUNCTION("""COMPUTED_VALUE"""),"Worlog 2") -> Worlog 2 | B14: =IFERROR(__xludf.DUMMYFUNCTION("""COMPUTED_VALUE"""),TRUE) -> TRUE | C14: =IFERROR(__xludf.DUMMYFUNCTION("""COMPUTED_VALUE"""),FALSE) -> FALSE | D14: =IFERROR(__xludf.DUMMYFUNCTION("""COMPUTED_VALUE"""),FALSE) -> FALSE | E14: =IFERROR(__xludf.DUMMYFUNCTION("""COMPUTED_VALUE"""),FALSE) -> FALSE | F14: =IFERROR(__xludf.DUMMYFUNCTION("""COMPUTED_VALUE"""),FALSE) -> FALSE | G14: =IFERROR(__xludf.DUMMYFUNCTION("""COMPUTED_VALUE"""),FALSE) -> FALSE | H14: =IFERROR(__xludf.DUMMYFUNCTION("""COMPUTED_VALUE"""),TRUE) -> TRUE | I14: =IFERROR(__xludf.DUMMYFUNCTION("""COMPUTED_VALUE"""),FALSE) -> FALSE | J14: =IFERROR(__xludf.DUMMYFUNCTION("""COMPUTED_VALUE"""),FALSE) -> FALSE | K14: =IFERROR(__xludf.DUMMYFUNCTION("""COMPUTED_VALUE"""),FALSE) -> FALSE | L14: =IFERROR(__xludf.DUMMYFUNCTION("""COMPUTED_VALUE"""),TRUE) -> TRUE | M14: =IFERROR(__xludf.DUMMYFUNCTION("""COMPUTED_VALUE"""),"Waylon and Noctara were amped, ""That was so fun!"" on exit. Arden Walked Through Shadows and looked proud.") -> Waylon and Noctara were amped, "That was so fun!" on exit. Arden Walked Through Shadows and looked proud. | U14: =IFERROR(__xludf.DUMMYFUNCTION("""COMPUTED_VALUE"""),"Waylon") -> Waylon | V14: =IFERROR(__xludf.DUMMYFUNCTION("""COMPUTED_VALUE"""),14.0) -> 14
